Workbook

Sheet Sheet1
A1: Country or Area | B1: Year | C1: Currency | D1: Primary | E1: Industry | F1: Construction | G1: Transportation | H1: Hospitality | I1: Financial | J1: Real Estate | K1: Other: Private | L1: Other: Public
A2: Antigua and Barbuda | B2: 2012 | C2: EC dollar | D2: 0.092307692 | E2: -0.27032967 | F2: 0.2956044 | G2: 0.024175824 | H2: 0.018681319 | I2: 0.13296703 | J2: -0.047252747 | K2: =Sheet2!K2+Sheet2!L2+Sheet2!B2+Sheet2!H2 -> 0.41098901 | L2: 0.35164835
A3: Antigua and Barbuda | B3: 2013 | C3: EC dollar | D3: -0.371875 | E3: 0.34375 | F3: 0.46875 | G3: 0.0875 | H3: 0.496875 | I3: -1.721875 | J3: -0.021875 | K3: =Sheet2!K3+Sheet2!L3+Sheet2!B3+Sheet2!H3 -> 1.215625 | L3: 0.50625
A4: Antigua and Barbuda | B4: 2014 | C4: EC dollar | D4: 0.0034482759 | E4: 0.11448276 | F4: 0.18689655 | G4: 0.07862069 | H4: 0.1737931 | I4: 0.0034482759 | J4: 0.045517241 | K4: =Sheet2!K4+Sheet2!L4+Sheet2!B4+Sheet2!H4 -> 0.20275862 | L4: 0.18482759
A5: Antigua and Barbuda | B5: 2015 | C5: EC dollar | D5: 0.018796992 | E5: 0.26466165 | F5: 0.082706767 | G5: 0.02406015 | H5: 0.23082707 | I5: 0.1 | J5: 0.034586466 | K5: =Sheet2!K5+Sheet2!L5+Sheet2!B5+Sheet2!H5 -> 0.018045113 | L5: 0.22556391
A6: Antigua and Barbuda | B6: 2016 | C6: EC dollar | D6: 0.021138211 | E6: 0.28130081 | F6: 0.50243902 | G6: 0.15691057 | H6: 0.16097561 | I6: -0.38699187 | J6: -0.10162602 | K6: =Sheet2!K6+Sheet2!L6+Sheet2!B6+Sheet2!H6 -> -0.10894309 | L6: 0.48065041
A7: Antigua and Barbuda | B7: 2017 | C7: EC dollar | D7: 0.087068966 | E7: -0.085344828 | F7: 0.64224138 | G7: -0.15775862 | H7: -0.084482759 | I7: 0.19396552 | J7: 0.14827586 | K7: =Sheet2!K7+Sheet2!L7+Sheet2!B7+Sheet2!H7 -> 0.15689655 | L7: 0.096034483
A8: Antigua and Barbuda | B8: 2018 | C8: EC dollar | D8: 0.014237288 | E8: 0.027457627 | F8: 0.47186441 | G8: 0.090508475 | H8: 0.10779661 | I8: -0.058983051 | J8: 0.034915254 | K8: =Sheet2!K8+Sheet2!L8+Sheet2!B8+Sheet2!H8 -> 0.13661017 | L8: 0.17474576
A9: Antigua and Barbuda | B9: 2019 | C9: EC dollar | D9: 0.019 | E9: 0.1135 | F9: 0.167 | G9: 0.3505 | H9: 0.0785 | I9: 0.035 | J9: 0.0855 | K9: =Sheet2!K9+Sheet2!L9+Sheet2!B9+Sheet2!H9 -> 0.044 | L9: 0.1108
A10: Antigua and Barbuda | B10: 2020 | C10: EC dollar | D10: -0.01309987 | E10: 0.048767834 | F10: 0.18158236 | G10: 0.23022049 | H10: 0.27094682 | I10: -0.0083009079 | J10: 0.030479896 | K10: =Sheet2!K10+Sheet2!L10+Sheet2!B10+Sheet2!H10 -> 0.22736706 | L10: 0.032645914
A11: Antigua and Barbuda | B11: 2021 | C11: EC dollar | D11: 0.0067391304 | E11: -0.038913043 | F11: 0.215 | G11: 0.15369565 | H11: 0.29152174 | I11: 0.17913043 | J11: 0.038695652 | K11: =Sheet2!K11+Sheet2!L11+Sheet2!B11+Sheet2!H11 -> 0.11586957 | L11: 0.037173913
A12: Antigua and Barbuda | B12: 2022 | C12: EC dollar | D12: 0.014214876 | E12: -0.010082645 | F12: 0.16892562 | G12: 0.18115702 | H12: 0.28049587 | I12: 0.029917355 | J12: 0.035867769 | K12: =Sheet2!K12+Sheet2!L12+Sheet2!B12+Sheet2!H12 -> 0.23553719 | L12: 0.065289256
A13: Bahamas | B13: 2013 | C13: Bahamian dollar | D13: 0.59449737 | E13: 0.6456587 | F13: 0.7452757 | G13: -2.4803151 | H13: 0.49247951 | I13: 2.2664309 | J13: 0.81491568 | K13: =Sheet2!K13+Sheet2!L13+Sheet2!B13+Sheet2!H13 -> -2.6413895 | L13: 0.56244676
... A283: Seychelles | B283: 2022 | C283: Seychelles rupee | D283: 0.043161515 | E283: 0.019580459 | F283: 0.12299364 | G283: 0.11102879 | H283: 0.35918437 | I283: 0.026534275 | J283: 0.054284138 | K283: =Sheet2!K283+Sheet2!L283+Sheet2!B283+Sheet2!H283 -> 0.14017476 | L283: 0.12305805
A284: Singapore | B284: 1971 | C284: Singapore dollar | D284: 0.027253467 | E284: 0.26964561 | F284: 0.10641371 | G284: 0.096976117 | H284: 0.036979969 | I284: 0.056336672 | K284: =Sheet2!K284+Sheet2!L284+Sheet2!B284+Sheet2!H284 -> 0.16746918
A285: Singapore | B285: 1972 | C285: Singapore dollar | D285: 0.0034975669 | E285: 0.31181569 | F285: 0.13899027 | G285: 0.10880474 | H285: 0.035355839 | I285: 0.070255474 | K285: =Sheet2!K285+Sheet2!L285+Sheet2!B285+Sheet2!H285 -> 0.13564477
A286: Singapore | B286: 1973 | C286: Singapore dollar | D286: 0.026788372 | E286: 0.28549459 | F286: 0.017412442 | G286: 0.085226709 | H286: 0.040430598 | I286: 0.087905546 | K286: =Sheet2!K286+Sheet2!L286+Sheet2!B286+Sheet2!H286 -> 0.30012898
A287: Singapore | B287: 1974 | C287: Singapore dollar | D287: 0.0083305975 | E287: 0.25812541 | F287: 0.081992777 | G287: 0.076124425 | H287: 0.023555483 | I287: 0.06824524 | K287: =Sheet2!K287+Sheet2!L287+Sheet2!B287+Sheet2!H287 -> 0.27921865
A288: Singapore | B288: 1975 | C288: Singapore dollar | D288: 0.043190883 | E288: 0.162849 | F288: 0.15430199 | G288: 0.14928775 | H288: 0.054131054 | I288: 0.22222222 | K288: =Sheet2!K288+Sheet2!L288+Sheet2!B288+Sheet2!H288 -> -0.00022792023
A289: Singapore | B289: 1976 | C289: Singapore dollar | D289: 0.0087247228 | E289: 0.32281474 | F289: 0.095401174 | G289: 0.20808871 | H289: 0.037181996 | I289: 0.082762557 | K289: =Sheet2!K289+Sheet2!L289+Sheet2!B289+Sheet2!H289 -> 0.11603066
A290: Singapore | B290: 1977 | C290: Singapore dollar | D290: 0.014928873 | E290: 0.31405346 | F290: -0.005393153 | G290: 0.2041582 | H290: 0.05010161 | I290: 0.033296858 | K290: =Sheet2!K290+Sheet2!L290+Sheet2!B290+Sheet2!H290 -> 0.27520713
A291: Singapore | B291: 1978 | C291: Singapore dollar | D291: -0.010680838 | E291: 0.33962959 | F291: -0.041197517 | G291: 0.21561612 | H291: 0.05014206 | I291: 0.11717352 | K291: =Sheet2!K291+Sheet2!L291+Sheet2!B291+Sheet2!H291 -> 0.2091971
A292: Singapore | B292: 1979 | C292: Singapore dollar | D292: 0.0082533518 | E292: 0.4228629 | F292: 0.038540539 | G292: 0.086828248 | H292: 0.045598835 | I292: 0.096276655 | K292: =Sheet2!K292+Sheet2!L292+Sheet2!B292+Sheet2!H292 -> 0.15722448
A293: Singapore | B293: 1980 | C293: Singapore dollar | D293: 0.013741357 | E293: 0.3621611 | F293: 0.080266975 | G293: 0.11741226 | H293: 0.045520972 | I293: 0.1486684 | K293: =Sheet2!K293+Sheet2!L293+Sheet2!B293+Sheet2!H293 -> 0.10059546
A294: Singapore | B294: 1981 | C294: Singapore dollar | D294: 0.012323539 | E294: 0.20333839 | F294: 0.12470686 | G294: 0.097530694 | H294: 0.042074769 | I294: 0.19598105 | K294: =Sheet2!K294+Sheet2!L294+Sheet2!B294+Sheet2!H294 -> 0.053685566
A295: Singapore | B295: 1982 | C295: Singapore dollar | D295: 0.0035106594 | E295: -0.029529175 | F295: 0.27799326 | G295: 0.079188018 | H295: 0.04705416 | I295: 0.14543756 | K295: =Sheet2!K295+Sheet2!L295+Sheet2!B295+Sheet2!H295 -> 0.11146344
... A318: Singapore | B318: 2005 | C318: Singapore dollar | D318: 0.00048139334 | E318: 0.25143336 | F318: 0.008984206 | G318: 0.079056685 | H318: 0.0066529641 | I318: 0.061726525 | K318: =Sheet2!K318+Sheet2!L318+Sheet2!B318+Sheet2!H318 -> 0.40604717
A319: Singapore | B319: 2006 | C319: Singapore dollar | D319: -7.371881e-05 | E319: 0.24603436 | F319: 0.020580557 | G319: 0.0062574261 | H319: 0.013984892 | I319: 0.16600609 | J319: 0.046447187 | K319: =Sheet2!K319+Sheet2!L319+Sheet2!B319+Sheet2!H319 -> 0.43866595 | L319: 0.062097257
A320: Singapore | B320: 2007 | C320: Singapore dollar | D320: 4.8558776e-05 | E320: 0.077723176 | F320: 0.052135939 | G320: 0.12286018 | H320: 0.018339031 | I320: 0.19618069 | J320: 0.10315179 | K320: =Sheet2!K320+Sheet2!L320+Sheet2!B320+Sheet2!H320 -> 0.38882306 | L320: 0.040737575
A321: Singapore | B321: 2008 | C321: Singapore dollar | D321: -0.0013429181 | E321: -3.3508966 | F321: 1.5306896 | G321: 0.21293151 | H321: 0.19168181 | I321: 0.24543803 | J321: 1.6687732 | K321: =Sheet2!K321+Sheet2!L321+Sheet2!B321+Sheet2!H321 -> -0.065802986 | L321: 0.56852832
A322: Singapore | B322: 2009 | C322: Singapore dollar | D322: 0.00016012261 | E322: 0.10422838 | F322: 0.34525866 | G322: -0.42568595 | H322: -0.043953656 | I322: 0.16009973 | J322: -0.017133119 | K322: =Sheet2!K322+Sheet2!L322+Sheet2!B322+Sheet2!H322 -> 0.77811581 | L322: 0.098910023
A323: Singapore | B323: 2010 | C323: Singapore dollar | D323: 8.1292602e-05 | E323: 0.28054816 | F323: -0.014465156 | G323: 0.094001345 | H323: 0.02697929 | I323: 0.059075087 | J323: 0.098602999 | K323: =Sheet2!K323+Sheet2!L323+Sheet2!B323+Sheet2!H323 -> 0.38799727 | L323: 0.067179713
A324: Singapore | B324: 2011 | C324: Singapore dollar | D324: 0.00015209942 | E324: 0.054831841 | F324: 0.019432938 | G324: -0.13920676 | H324: 0.051982213 | I324: 0.058625379 | J324: 0.19460673 | K324: =Sheet2!K324+Sheet2!L324+Sheet2!B324+Sheet2!H324 -> 0.67248522 | L324: 0.087090338
A325: Singapore | B325: 2012 | C325: Singapore dollar | D325: 6.7828382e-05 | E325: 0.11930396 | F325: 0.097771529 | G325: 0.095187885 | H325: 0.038212044 | I325: 0.14945059 | J325: 0.19085673 | K325: =Sheet2!K325+Sheet2!L325+Sheet2!B325+Sheet2!H325 -> 0.22127468 | L325: 0.087874752
A326: Singapore | B326: 2013 | C326: Singapore dollar | D326: 0.0006365499 | E326: -0.18217262 | F326: 0.046216175 | G326: 0.069874613 | H326: 0.023917036 | I326: 0.34255668 | J326: 0.24314217 | K326: =Sheet2!K326+Sheet2!L326+Sheet2!B326+Sheet2!H326 -> 0.27947856 | L326: 0.17635085
A327: Singapore | B327: 2014 | C327: Singapore dollar | D327: 0.00037932866 | E327: 0.28522067 | F327: 0.14208962 | G327: 0.16109054 | H327: 0.031608422 | I327: 0.21229301 | J327: 0.018325023 | K327: =Sheet2!K327+Sheet2!L327+Sheet2!B327+Sheet2!H327 -> 0.010145317 | L327: 0.13884808
A328: Singapore | B328: 2015 | C328: Singapore dollar | D328: 1.3643433e-05 | E328: 0.23537197 | F328: 0.05688857 | G328: 0.13291433 | H328: 0.0043886377 | I328: 0.17762841 | J328: 0.0055346862 | K328: =Sheet2!K328+Sheet2!L328+Sheet2!B328+Sheet2!H328 -> 0.27682072 | L328: 0.11043905
A329: Singapore | B329: 2016 | C329: Singapore dollar | D329: 7.3245927e-05 | E329: 0.019030623 | F329: -0.044626745 | G329: -0.15069351 | H329: 0.028505983 | I329: 0.10996211 | J329: -0.1253038 | K329: =Sheet2!K329+Sheet2!L329+Sheet2!B329+Sheet2!H329 -> 1.0112932 | L329: 0.1517589
A330: Singapore | B330: 2017 | C330: Singapore dollar | D330: 0.00021982782 | E330: 0.35161137 | F330: -0.059049633 | G330: 0.1245066 | H330: 0.0051142296 | I330: 0.16914458 | J330: -0.060530238 | K330: =Sheet2!K330+Sheet2!L330+Sheet2!B330+Sheet2!H330 -> 0.40716639 | L330: 0.061813644
... A343: Suriname | B343: 2022 | C343: Suriname dollar | D343: 0.064834261 | E343: 0.49814899 | F343: 0.11046918 | G343: 0.045733231 | H343: 0.023496676 | I343: 0.12074986 | J343: 0.018689729 | K343: =Sheet2!K343+Sheet2!L343+Sheet2!B343+Sheet2!H343 -> 0.056458681 | L343: 0.061417709
...

Sheet Sheet2
A1: M | B1: M+N | C1: N | D1: O | E1: P | F1: Q | G1: R | H1: R+S+T | I1: S | J1: T | K1: G | L1: J
A2: 0.024175824 | B2: 0.0054945055 | C2: -0.018681319 | D2: 0.087912088 | E2: 0.19340659 | F2: 0.07032967 | G2: 0.037362637 | H2: 0.036263736 | I2: -0.0032967033 | J2: 0.0021978022 | K2: 0.26483516 | L2: 0.1043956
A3: 0.053125 | B3: 0.171875 | C3: 0.11875 | D3: -0.221875 | E3: 0.571875 | F3: 0.15625 | G3: 0.096875 | H3: 0.175 | I3: 0.0625 | J3: 0.015625 | K3: 0.68125 | L3: 0.1875
A4: 0.013103448 | B4: 0.026896552 | C4: 0.013793103 | D4: 0.19172414 | E4: -0.05862069 | F4: 0.051724138 | G4: 0.084827586 | H4: 0.099310345 | I4: 0.014482759 | J4: 0 | K4: 0.026206897 | L4: 0.050344828
A5: 0.015037594 | B5: 0.057142857 | C5: 0.042105263 | D5: 0.042105263 | E5: -0.0090225564 | F5: 0.1924812 | G5: -0.026315789 | H5: -0.029323308 | I5: 0 | J5: -0.0030075188 | K5: -0.087969925 | L5: 0.078195489
A6: 0.034146341 | B6: 0.064227642 | C6: 0.030081301 | D6: 0.12536585 | E6: 0.27642276 | F6: 0.078861789 | G6: -0.11707317 | H6: -0.13577236 | I6: 0.0081300813 | J6: -0.026829268 | K6: -0.05203252 | L6: 0.014634146
A7: -0.034482759 | B7: -0.025 | C7: 0.0094827586 | D7: 0.077931034 | E7: -0.017241379 | F7: 0.035344828 | G7: 0.072413793 | H7: 0.063793103 | I7: 0.0034482759 | J7: -0.012068966 | K7: 0.15172414 | L7: -0.03362069
A8: 0.0081355932 | B8: 0.023728814 | C8: 0.01559322 | D8: 0.12186441 | E8: 0.021694915 | F8: 0.031186441 | G8: -0.034576271 | H8: -0.041694915 | I8: -0.0027118644 | J8: -0.0044067797 | K8: 0.11118644 | L8: 0.043389831
A9: -0.004 | B9: -0.004 | C9: 0 | D9: 0.0963 | E9: -0.0265 | F9: 0.041 | G9: 0 | H9: 0.022 | I9: 0.0215 | J9: 0.0005 | K9: 0.174 | L9: -0.148
A10: 0.0055771725 | B10: 0.014396887 | C10: 0.0088197147 | D10: 0.015654994 | E10: 0.013748379 | F10: 0.0032425422 | G10: 0.024383917 | H10: 0.0307393 | I10: 0.0063553826 | J10: 0 | K10: 0.1613489 | L10: 0.020881971
A11: 0.012826087 | B11: 0.014130435 | C11: 0.0013043478 | D11: 0.010869565 | E11: 0.012173913 | F11: 0.014130435 | G11: -0.0082608696 | H11: -0.0063043478 | I11: 0.0045652174 | J11: -0.0026086957 | K11: 0.13673913 | L11: -0.028695652
A12: 0.0039669421 | B12: 0.0041322314 | C12: 0.00016528926 | D12: 0.036363636 | E12: 0.010743802 | F12: 0.018181818 | G12: 0.007768595 | H12: 0.0094214876 | I12: 0.0033057851 | J12: -0.0016528926 | K12: 0.23190083 | L12: -0.0099173554
A13: -0.72007387 | B13: -1.2575135 | C13: -0.53743966 | D13: -2.0000468 | E13: 0.030799028 | F13: 2.5316946 | H13: -1.1753122 | K13: 1.5932607 | L13: -1.8018244
A14: 0.051228925 | B14: 0.15000066 | C14: 0.098771738 | D14: 0.10394181 | E14: -0.0092474861 | F14: 0.02846579 | H14: 0.043773241 | K14: 0.29527984 | L14: 0.15545154
A15: 0.16948647 | B15: 0.2194676 | C15: 0.049981129 | D15: 0.15237303 | E15: -0.014400976 | F15: 0.10919151 | H15: 0.3039607 | K15: -0.70334856 | L15: -0.027373689
A16: 0.0088099831 | B16: -0.069505171 | C16: -0.078315154 | D16: 0.058567508 | E16: 0.058752336 | F16: 0.0752673 | H16: 0.10027871 | K16: 0.48190838 | L16: -0.072471851
A17: 0.15089326 | B17: 0.38100671 | C17: 0.23011345 | D17: 0.22526517 | E17: 0.014135459 | F17: 0.0077261922 | H17: 0.027742046 | K17: -0.66363165 | L17: -0.060059809
A18: -0.050292548 | B18: -0.12692142 | C18: -0.076628876 | D18: 0.021661533 | E18: -0.049726962 | F18: 0.061718328 | H18: 0.12576393 | K18: 0.10972238 | L18: 0.026358291
A19: 0.3454947 | B19: 0.42295641 | C19: 0.077461708 | D19: 0.10019388 | E19: 0.040459805 | F19: -0.082810736 | H19: 0.13071778 | K19: 0.23337193 | L19: -0.21991722
A20: 0.038330719 | B20: 0.075268899 | C20: 0.03693818 | D20: 0.0066726447 | E20: 0.0078335036 | F20: -0.009103228 | H20: 0.1450973 | K20: 0.060559582 | L20: -0.0026141745
A21: 0.051802306 | B21: 0.058607794 | C21: 0.0068054878 | D21: -0.020669471 | E21: 0.010381202 | F21: 0.016178813 | H21: 0.174997 | K21: 0.07330442 | L21: 0.013561882
A22: 0.042269354 | B22: 0.093301714 | C22: 0.05103236 | D22: 0.027270833 | E22: 0.0046105773 | F22: -0.0024906141 | H22: 0.09844016 | K22: 0.14163116 | L22: 0.02383257
A23: -0.02482419 | B23: 0.02473771 | C23: 0.0495619 | D23: 0.042354508 | E23: 0.013816163 | F23: 0.0072834789 | H23: 0.24164105 | K23: -0.10968902 | L23: -0.0019821312
B24: -0.12514953 | D24: -0.031317769 | E24: -0.031493817 | F24: -0.14735516 | H24: 0.04142189 | I24: 0.017604418 | J24: 0.023817472 | K24: 0.78441292 | L24: 0.16442773
B25: 1.3808101 | D25: -0.064367979 | E25: -0.15417344 | F25: -0.075395959 | H25: -0.10632613 | I25: 0.0020797144 | J25: -0.10840584 | K25: 0.34553385 | L25: -0.10077923
B26: 0.20752994 | D26: 0.010236898 | E26: 0.010259665 | F26: -0.022874412 | H26: 0.073842302 | I26: 0.031963711 | J26: 0.041878591 | K26: 0.10417923 | L26: -0.12990987
B27: 0.46562539 | D27: 1.1509519 | E27: 0.18757648 | F27: 0.41293912 | H27: -0.59037367 | I27: -0.32234158 | J27: -0.26803209 | K27: 0.30535648 | L27: 0.82082359
B28: 0.71376936 | D28: 0.24427415 | E28: -0.28796489 | F28: 0.11420138 | H28: 0.03537296 | I28: 0.035368768 | J28: 4.19284e-06 | K28: 0.4761879 | L28: 0.26580973
B29: -0.10591575 | D29: -0.46939801 | E29: 0.42531359 | F29: 0.16218765 | H29: 0.088338735 | I29: 0.10631909 | J29: -0.017980359 | K29: -0.23519585 | L29: 0.21929502
B30: 0.11090733 | D30: -0.060476085 | E30: 0.15626024 | F30: 0.023586778 | H30: -0.049708763 | I30: -0.033018528 | J30: -0.016690235 | K30: 0.07671352 | L30: -0.1045399
B31: -0.061696475 | D31: -0.053717047 | E31: 0.05294962 | F31: 0.058116632 | H31: 1.7825187e-05 | I31: 2.002283e-05 | J31: -2.1976432e-06 | K31: -0.0038251578 | L31: -0.11974838
B32: 0.033102276 | D32: -0.064526647 | E32: 0.24834229 | F32: -0.040012726 | H32: -0.012803082 | I32: -0.012804929 | J32: 1.8475016e-06 | K32: 0.03733499 | L32: 0.016765062
B33: 0.0039175822 | D33: -0.0027846768 | E33: -0.125489 | F33: -0.022848801 | H33: 0.078340479 | I33: 0.067063983 | J33: 0.011276497 | K33: 0.069308105 | L33: 0.030831449
B34: 0.74631242 | D34: 0.63337017 | E34: -2.4956701 | F34: 2.4619274 | H34: -2.1726999 | I34: -1.6571144 | J34: -0.5155855 | K34: 3.1755795 | L34: 1.59059
B35: 0.07400422 | D35: 0.040110951 | E35: 0.050235695 | F35: 0.0043793077 | H35: 0.047210017 | I35: 0.029315368 | J35: 0.017894649 | K35: 0.14669663 | L35: 0.01995337
B36: 0.044803473 | D36: 0.04984537 | E36: 0.18560056 | F36: 0.027273401 | H36: 0.031219839 | I36: 0.019730971 | J36: 0.011488868 | K36: 0.043899523 | L36: 0.034276023
A37: 0.014006161 | B37: 0.030977262 | C37: 0.0169711 | D37: 0.065895993 | E37: 0.067259075 | F37: 0.019437872 | G37: 0.017318046 | H37: 0.033380435 | I37: 0.0075062604 | J37: 0.0085561289 | K37: 0.20253865 | L37: 0.068972504
A38: 0.014684381 | B38: 0.037803837 | C38: 0.023119456 | D38: 0.094203253 | E38: 0.041248567 | F38: 0.0075754816 | G38: 0.012752565 | H38: 0.010931537 | I38: -0.0042371928 | J38: 0.002416164 | K38: 0.26939832 | L38: 0.047009275
A39: 0.020273351 | B39: 0.030839386 | C39: 0.010566035 | D39: 0.14149119 | E39: 0.11191922 | F39: 0.014089027 | G39: 0.0058048942 | H39: 0.018503625 | I39: 0.0096378233 | J39: 0.0030609077 | K39: 0.14179618 | L39: 0.070066164
A40: -0.055347637 | B40: 0.057376123 | C40: 0.11272376 | D40: 0.29700577 | E40: 0.23260313 | F40: 0.025106451 | G40: 0.040955743 | H40: 0.086696195 | I40: 0.03254208 | J40: 0.013198371 | K40: 0.095022886 | L40: -0.030594885
...
